Workbook

Sheet Dashboard
A1: KWSP i-Akaun UX Audit - Project Dashboard
A2: Live tracker: overall progress, health, mandays and key alerts · Auto-updates from all sheets
A3: Project Start Date: | B3: 46148 | C3: <- Enter project start date here | D3: End Date: | E3: =IFERROR(MAX('Task Tracker'!$J$8:$J$203),"") -> 46276 | F3: ← auto: Start + 14 weeks | G3: Today: | H3: =TODAY() -> 46181 | J3: UXR Lead: | K3: Faznur | M3: Status: | N3: =IF(COUNTIFS('Task Tracker'!$M$8:$M$203,"Delayed")>0,"Delayed",IF(COUNTIFS('Task Tracker'!$M$8:$M$203,"Check*")>0,"Check Tracker",IF(SUMPRODUCT('Task Tracker'!$H$8:$H$203,'Task Tracker'!$N$8:$N$203)=SUM('Task Tracker'!$H$8:$H$203),"Complete",IF(COUNTIFS('Task Tracker'!$M$8:$M$203,"In Progress")>0,"In Progress","Not Started")))) -> Delayed
A5: OVERALL PROGRESS | D5: TASKS COMPLETE | G5: TASKS DELAYED | J5: MANDAYS USED | M5: MANDAYS REMAINING
A6: =IFERROR(SUMPRODUCT('Task Tracker'!$H$8:$H$203,'Task Tracker'!$N$8:$N$203)/SUM('Task Tracker'!$H$8:$H$203),0) -> 0.11384803 | D6: =COUNTIFS('Task Tracker'!$L$8:$L$203,">0",'Task Tracker'!$L$8:$L$203,"<="&$H$3) -> 3 | G6: =COUNTIFS('Task Tracker'!$M$8:$M$203,"Delayed") -> 1 | J6: =IFERROR(SUMPRODUCT('Task Tracker'!$H$8:$H$203,'Task Tracker'!$N$8:$N$203),0) -> 27.778919 | M6: =IFERROR(SUM('Task Tracker'!$H$8:$H$203)-SUMPRODUCT('Task Tracker'!$H$8:$H$203,'Task Tracker'!$N$8:$N$203),0) -> 216.22108
A11: Workstream | B11: Weeks | C11: Total Tasks | D11: Complete | E11: In Progress | F11: Not Started | G11: % Done | H11: Status | I11: Expected Start | J11: Expected End
A12: Setup | B12: {=IF(C12=0,"",_xlfn.LET(_xlpm.startW,_xlfn._xlws.FILTER('Task Tracker'!$E$8:$E$203,(TRIM('Task Tracker'!$B$8:$B$203)=TRIM($A12))*('Task Tracker'!$E$8:$E$203<>"")),_xlpm.endW,_xlfn._xlws.FILTER('Task Tracker'!$F$8:$F$203,(TRIM('Task Tracker'!$B$8:$B$203)=TRIM($A12))*('Task Tracker'!$F$8:$F$203<>"")),_xlpm.minW,MIN(--SUBSTITUTE(_xlpm.startW,"W","")),_xlpm.maxW,MAX(--SUBSTITUTE(_xlpm.endW,"W","")),IF(_xlpm.minW=_xlpm.maxW,"W"&_xlpm.minW,"W"&_xlpm.minW&"-"&"W"&_xlpm.maxW)))} -> W0-W4 | C12: {=SUMPRODUCT(--(TRIM('Task Tracker'!$B$8:$B$203)=TRIM($A12)),--('Task Tracker'!$D$8:$D$203<>""))} -> 5 | D12: {=SUMPRODUCT(--(TRIM('Task Tracker'!$B$8:$B$203)=TRIM($A12)),--(LEFT('Task Tracker'!$M$8:$M$203,9)="Completed"))} -> 2 | E12: {=SUMPRODUCT(--(TRIM('Task Tracker'!$B$8:$B$203)=TRIM($A12)),--('Task Tracker'!$M$8:$M$203="In Progress"))} -> 0 | F12: {=SUMPRODUCT(--(TRIM('Task Tracker'!$B$8:$B$203)=TRIM($A12)),--((('Task Tracker'!$M$8:$M$203="Not Started")+('Task Tracker'!$M$8:$M$203="Due to Start"))>0))} -> 2 | G12: {=IFERROR(SUMPRODUCT(--(TRIM('Task Tracker'!$B$8:$B$203)=TRIM($A12)),'Task Tracker'!$H$8:$H$203,'Task Tracker'!$N$8:$N$203)/SUMPRODUCT(--(TRIM('Task Tracker'!$B$8:$B$203)=TRIM($A12)),'Task Tracker'!$H$8:$H$203),0)} -> 0.77913043 | H12: {=IF(C12=0,"",IF(SUMPRODUCT(--(TRIM('Task Tracker'!$B$8:$B$203)=TRIM($A12)),--(LEFT('Task Tracker'!$M$8:$M$203,5)="Check"))>0,"Check Tracker",IF(D12=C12,"Complete",IF(SUMPRODUCT(--(TRIM('Task Tracker'!$B$8:$B$203)=TRIM($A12)),--('Task Tracker'!$M$8:$M$203="Delayed"))>0,"Delayed",IF(E12>0,"In Progress","Not Started")))))} -> Delayed | I12: {=IFERROR(MIN(_xlfn._xlws.FILTER('Task Tracker'!$I$8:$I$203,TRIM('Task Tracker'!$B$8:$B$203)=TRIM($A12))),"")} -> 46148 | J12: {=IFERROR(MAX(_xlfn._xlws.FILTER('Task Tracker'!$J$8:$J$203,TRIM('Task Tracker'!$B$8:$B$203)=TRIM($A12))),"")} -> 46195
A13: Heuristics Study | B13: {=IF(C13=0,"",_xlfn.LET(_xlpm.startW,_xlfn._xlws.FILTER('Task Tracker'!$E$8:$E$203,(TRIM('Task Tracker'!$B$8:$B$203)=TRIM($A13))*('Task Tracker'!$E$8:$E$203<>"")),_xlpm.endW,_xlfn._xlws.FILTER('Task Tracker'!$F$8:$F$203,(TRIM('Task Tracker'!$B$8:$B$203)=TRIM($A13))*('Task Tracker'!$F$8:$F$203<>"")),_xlpm.minW,MIN(--SUBSTITUTE(_xlpm.startW,"W","")),_xlpm.maxW,MAX(--SUBSTITUTE(_xlpm.endW,"W","")),IF(_xlpm.minW=_xlpm.maxW,"W"&_xlpm.minW,"W"&_xlpm.minW&"-"&"W"&_xlpm.maxW)))} -> W4-W7 | C13: {=SUMPRODUCT(--(TRIM('Task Tracker'!$B$8:$B$203)=TRIM($A13)),--('Task Tracker'!$D$8:$D$203<>""))} -> 6 | D13: {=SUMPRODUCT(--(TRIM('Task Tracker'!$B$8:$B$203)=TRIM($A13)),--(LEFT('Task Tracker'!$M$8:$M$203,9)="Completed"))} -> 0 | E13: {=SUMPRODUCT(--(TRIM('Task Tracker'!$B$8:$B$203)=TRIM($A13)),--('Task Tracker'!$M$8:$M$203="In Progress"))} -> 0 | F13: {=SUMPRODUCT(--(TRIM('Task Tracker'!$B$8:$B$203)=TRIM($A13)),--((('Task Tracker'!$M$8:$M$203="Not Started")+('Task Tracker'!$M$8:$M$203="Due to Start"))>0))} -> 6 | G13: {=IFERROR(SUMPRODUCT(--(TRIM('Task Tracker'!$B$8:$B$203)=TRIM($A13)),'Task Tracker'!$H$8:$H$203,'Task Tracker'!$N$8:$N$203)/SUMPRODUCT(--(TRIM('Task Tracker'!$B$8:$B$203)=TRIM($A13)),'Task Tracker'!$H$8:$H$203),0)} -> 0 | H13: {=IF(C13=0,"",IF(SUMPRODUCT(--(TRIM('Task Tracker'!$B$8:$B$203)=TRIM($A13)),--(LEFT('Task Tracker'!$M$8:$M$203,5)="Check"))>0,"Check Tracker",IF(D13=C13,"Complete",IF(SUMPRODUCT(--(TRIM('Task Tracker'!$B$8:$B$203)=TRIM($A13)),--('Task Tracker'!$M$8:$M$203="Delayed"))>0,"Delayed",IF(E13>0,"In Progress","Not Started")))))} -> Not Started | I13: {=IFERROR(MIN(_xlfn._xlws.FILTER('Task Tracker'!$I$8:$I$203,TRIM('Task Tracker'!$B$8:$B$203)=TRIM($A13))),"")} -> 46191 | J13: {=IFERROR(MAX(_xlfn._xlws.FILTER('Task Tracker'!$J$8:$J$203,TRIM('Task Tracker'!$B$8:$B$203)=TRIM($A13))),"")} -> 46216
A14: Analytics Review | B14: {=IF(C14=0,"",_xlfn.LET(_xlpm.startW,_xlfn._xlws.FILTER('Task Tracker'!$E$8:$E$203,(TRIM('Task Tracker'!$B$8:$B$203)=TRIM($A14))*('Task Tracker'!$E$8:$E$203<>"")),_xlpm.endW,_xlfn._xlws.FILTER('Task Tracker'!$F$8:$F$203,(TRIM('Task Tracker'!$B$8:$B$203)=TRIM($A14))*('Task Tracker'!$F$8:$F$203<>"")),_xlpm.minW,MIN(--SUBSTITUTE(_xlpm.startW,"W","")),_xlpm.maxW,MAX(--SUBSTITUTE(_xlpm.endW,"W","")),IF(_xlpm.minW=_xlpm.maxW,"W"&_xlpm.minW,"W"&_xlpm.minW&"-"&"W"&_xlpm.maxW)))} -> W4-W6 | C14: {=SUMPRODUCT(--(TRIM('Task Tracker'!$B$8:$B$203)=TRIM($A14)),--('Task Tracker'!$D$8:$D$203<>""))} -> 3 | D14: {=SUMPRODUCT(--(TRIM('Task Tracker'!$B$8:$B$203)=TRIM($A14)),--(LEFT('Task Tracker'!$M$8:$M$203,9)="Completed"))} -> 0 | E14: {=SUMPRODUCT(--(TRIM('Task Tracker'!$B$8:$B$203)=TRIM($A14)),--('Task Tracker'!$M$8:$M$203="In Progress"))} -> 0 | F14: {=SUMPRODUCT(--(TRIM('Task Tracker'!$B$8:$B$203)=TRIM($A14)),--((('Task Tracker'!$M$8:$M$203="Not Started")+('Task Tracker'!$M$8:$M$203="Due to Start"))>0))} -> 3 | G14: {=IFERROR(SUMPRODUCT(--(TRIM('Task Tracker'!$B$8:$B$203)=TRIM($A14)),'Task Tracker'!$H$8:$H$203,'Task Tracker'!$N$8:$N$203)/SUMPRODUCT(--(TRIM('Task Tracker'!$B$8:$B$203)=TRIM($A14)),'Task Tracker'!$H$8:$H$203),0)} -> 0 | H14: {=IF(C14=0,"",IF(SUMPRODUCT(--(TRIM('Task Tracker'!$B$8:$B$203)=TRIM($A14)),--(LEFT('Task Tracker'!$M$8:$M$203,5)="Check"))>0,"Check Tracker",IF(D14=C14,"Complete",IF(SUMPRODUCT(--(TRIM('Task Tracker'!$B$8:$B$203)=TRIM($A14)),--('Task Tracker'!$M$8:$M$203="Delayed"))>0,"Delayed",IF(E14>0,"In Progress","Not Started")))))} -> Not Started | I14: {=IFERROR(MIN(_xlfn._xlws.FILTER('Task Tracker'!$I$8:$I$203,TRIM('Task Tracker'!$B$8:$B$203)=TRIM($A14))),"")} -> 46191 | J14: {=IFERROR(MAX(_xlfn._xlws.FILTER('Task Tracker'!$J$8:$J$203,TRIM('Task Tracker'!$B$8:$B$203)=TRIM($A14))),"")} -> 46209
A15: Benchmarking and Peer Study | B15: {=IF(C15=0,"",_xlfn.LET(_xlpm.startW,_xlfn._xlws.FILTER('Task Tracker'!$E$8:$E$203,(TRIM('Task Tracker'!$B$8:$B$203)=TRIM($A15))*('Task Tracker'!$E$8:$E$203<>"")),_xlpm.endW,_xlfn._xlws.FILTER('Task Tracker'!$F$8:$F$203,(TRIM('Task Tracker'!$B$8:$B$203)=TRIM($A15))*('Task Tracker'!$F$8:$F$203<>"")),_xlpm.minW,MIN(--SUBSTITUTE(_xlpm.startW,"W","")),_xlpm.maxW,MAX(--SUBSTITUTE(_xlpm.endW,"W","")),IF(_xlpm.minW=_xlpm.maxW,"W"&_xlpm.minW,"W"&_xlpm.minW&"-"&"W"&_xlpm.maxW)))} -> W4-W6 | C15: {=SUMPRODUCT(--(TRIM('Task Tracker'!$B$8:$B$203)=TRIM($A15)),--('Task Tracker'!$D$8:$D$203<>""))} -> 2 | D15: {=SUMPRODUCT(--(TRIM('Task Tracker'!$B$8:$B$203)=TRIM($A15)),--(LEFT('Task Tracker'!$M$8:$M$203,9)="Completed"))} -> 0 | E15: {=SUMPRODUCT(--(TRIM('Task Tracker'!$B$8:$B$203)=TRIM($A15)),--('Task Tracker'!$M$8:$M$203="In Progress"))} -> 0 | F15: {=SUMPRODUCT(--(TRIM('Task Tracker'!$B$8:$B$203)=TRIM($A15)),--((('Task Tracker'!$M$8:$M$203="Not Started")+('Task Tracker'!$M$8:$M$203="Due to Start"))>0))} -> 2 | G15: {=IFERROR(SUMPRODUCT(--(TRIM('Task Tracker'!$B$8:$B$203)=TRIM($A15)),'Task Tracker'!$H$8:$H$203,'Task Tracker'!$N$8:$N$203)/SUMPRODUCT(--(TRIM('Task Tracker'!$B$8:$B$203)=TRIM($A15)),'Task Tracker'!$H$8:$H$203),0)} -> 0 | H15: {=IF(C15=0,"",IF(SUMPRODUCT(--(TRIM('Task Tracker'!$B$8:$B$203)=TRIM($A15)),--(LEFT('Task Tracker'!$M$8:$M$203,5)="Check"))>0,"Check Tracker",IF(D15=C15,"Complete",IF(SUMPRODUCT(--(TRIM('Task Tracker'!$B$8:$B$203)=TRIM($A15)),--('Task Tracker'!$M$8:$M$203="Delayed"))>0,"Delayed",IF(E15>0,"In Progress","Not Started")))))} -> Not Started | I15: {=IFERROR(MIN(_xlfn._xlws.FILTER('Task Tracker'!$I$8:$I$203,TRIM('Task Tracker'!$B$8:$B$203)=TRIM($A15))),"")} -> 46191 | J15: {=IFERROR(MAX(_xlfn._xlws.FILTER('Task Tracker'!$J$8:$J$203,TRIM('Task Tracker'!$B$8:$B$203)=TRIM($A15))),"")} -> 46209
A16: Field Research | B16: {=IF(C16=0,"",_xlfn.LET(_xlpm.startW,_xlfn._xlws.FILTER('Task Tracker'!$E$8:$E$203,(TRIM('Task Tracker'!$B$8:$B$203)=TRIM($A16))*('Task Tracker'!$E$8:$E$203<>"")),_xlpm.endW,_xlfn._xlws.FILTER('Task Tracker'!$F$8:$F$203,(TRIM('Task Tracker'!$B$8:$B$203)=TRIM($A16))*('Task Tracker'!$F$8:$F$203<>"")),_xlpm.minW,MIN(--SUBSTITUTE(_xlpm.startW,"W","")),_xlpm.maxW,MAX(--SUBSTITUTE(_xlpm.endW,"W","")),IF(_xlpm.minW=_xlpm.maxW,"W"&_xlpm.minW,"W"&_xlpm.minW&"-"&"W"&_xlpm.maxW)))} -> W6-W11 | C16: {=SUMPRODUCT(--(TRIM('Task Tracker'!$B$8:$B$203)=TRIM($A16)),--('Task Tracker'!$D$8:$D$203<>""))} -> 7 | D16: {=SUMPRODUCT(--(TRIM('Task Tracker'!$B$8:$B$203)=TRIM($A16)),--(LEFT('Task Tracker'!$M$8:$M$203,9)="Completed"))} -> 0 | E16: {=SUMPRODUCT(--(TRIM('Task Tracker'!$B$8:$B$203)=TRIM($A16)),--('Task Tracker'!$M$8:$M$203="In Progress"))} -> 0 | F16: {=SUMPRODUCT(--(TRIM('Task Tracker'!$B$8:$B$203)=TRIM($A16)),--((('Task Tracker'!$M$8:$M$203="Not Started")+('Task Tracker'!$M$8:$M$203="Due to Start"))>0))} -> 7 | G16: {=IFERROR(SUMPRODUCT(--(TRIM('Task Tracker'!$B$8:$B$203)=TRIM($A16)),'Task Tracker'!$H$8:$H$203,'Task Tracker'!$N$8:$N$203)/SUMPRODUCT(--(TRIM('Task Tracker'!$B$8:$B$203)=TRIM($A16)),'Task Tracker'!$H$8:$H$203),0)} -> 0 | H16: {=IF(C16=0,"",IF(SUMPRODUCT(--(TRIM('Task Tracker'!$B$8:$B$203)=TRIM($A16)),--(LEFT('Task Tracker'!$M$8:$M$203,5)="Check"))>0,"Check Tracker",IF(D16=C16,"Complete",IF(SUMPRODUCT(--(TRIM('Task Tracker'!$B$8:$B$203)=TRIM($A16)),--('Task Tracker'!$M$8:$M$203="Delayed"))>0,"Delayed",IF(E16>0,"In Progress","Not Started")))))} -> Not Started | I16: {=IFERROR(MIN(_xlfn._xlws.FILTER('Task Tracker'!$I$8:$I$203,TRIM('Task Tracker'!$B$8:$B$203)=TRIM($A16))),"")} -> 46210 | J16: {=IFERROR(MAX(_xlfn._xlws.FILTER('Task Tracker'!$J$8:$J$203,TRIM('Task Tracker'!$B$8:$B$203)=TRIM($A16))),"")} -> 46245
A17: Analysis | B17: {=IF(C17=0,"",_xlfn.LET(_xlpm.startW,_xlfn._xlws.FILTER('Task Tracker'!$E$8:$E$203,(TRIM('Task Tracker'!$B$8:$B$203)=TRIM($A17))*('Task Tracker'!$E$8:$E$203<>"")),_xlpm.endW,_xlfn._xlws.FILTER('Task Tracker'!$F$8:$F$203,(TRIM('Task Tracker'!$B$8:$B$203)=TRIM($A17))*('Task Tracker'!$F$8:$F$203<>"")),_xlpm.minW,MIN(--SUBSTITUTE(_xlpm.startW,"W","")),_xlpm.maxW,MAX(--SUBSTITUTE(_xlpm.endW,"W","")),IF(_xlpm.minW=_xlpm.maxW,"W"&_xlpm.minW,"W"&_xlpm.minW&"-"&"W"&_xlpm.maxW)))} -> W11-W13 | C17: {=SUMPRODUCT(--(TRIM('Task Tracker'!$B$8:$B$203)=TRIM($A17)),--('Task Tracker'!$D$8:$D$203<>""))} -> 5 | D17: {=SUMPRODUCT(--(TRIM('Task Tracker'!$B$8:$B$203)=TRIM($A17)),--(LEFT('Task Tracker'!$M$8:$M$203,9)="Completed"))} -> 0 | E17: {=SUMPRODUCT(--(TRIM('Task Tracker'!$B$8:$B$203)=TRIM($A17)),--('Task Tracker'!$M$8:$M$203="In Progress"))} -> 0 | F17: {=SUMPRODUCT(--(TRIM('Task Tracker'!$B$8:$B$203)=TRIM($A17)),--((('Task Tracker'!$M$8:$M$203="Not Started")+('Task Tracker'!$M$8:$M$203="Due to Start"))>0))} -> 5 | G17: {=IFERROR(SUMPRODUCT(--(TRIM('Task Tracker'!$B$8:$B$203)=TRIM($A17)),'Task Tracker'!$H$8:$H$203,'Task Tracker'!$N$8:$N$203)/SUMPRODUCT(--(TRIM('Task Tracker'!$B$8:$B$203)=TRIM($A17)),'Task Tracker'!$H$8:$H$203),0)} -> 0 | H17: {=IF(C17=0,"",IF(SUMPRODUCT(--(TRIM('Task Tracker'!$B$8:$B$203)=TRIM($A17)),--(LEFT('Task Tracker'!$M$8:$M$203,5)="Check"))>0,"Check Tracker",IF(D17=C17,"Complete",IF(SUMPRODUCT(--(TRIM('Task Tracker'!$B$8:$B$203)=TRIM($A17)),--('Task Tracker'!$M$8:$M$203="Delayed"))>0,"Delayed",IF(E17>0,"In Progress","Not Started")))))} -> Not Started | I17: {=IFERROR(MIN(_xlfn._xlws.FILTER('Task Tracker'!$I$8:$I$203,TRIM('Task Tracker'!$B$8:$B$203)=TRIM($A17))),"")} -> 46246 | J17: {=IFERROR(MAX(_xlfn._xlws.FILTER('Task Tracker'!$J$8:$J$203,TRIM('Task Tracker'!$B$8:$B$203)=TRIM($A17))),"")} -> 46261
A18: Recommendations | B18: {=IF(C18=0,"",_xlfn.LET(_xlpm.startW,_xlfn._xlws.FILTER('Task Tracker'!$E$8:$E$203,(TRIM('Task Tracker'!$B$8:$B$203)=TRIM($A18))*('Task Tracker'!$E$8:$E$203<>"")),_xlpm.endW,_xlfn._xlws.FILTER('Task Tracker'!$F$8:$F$203,(TRIM('Task Tracker'!$B$8:$B$203)=TRIM($A18))*('Task Tracker'!$F$8:$F$203<>"")),_xlpm.minW,MIN(--SUBSTITUTE(_xlpm.startW,"W","")),_xlpm.maxW,MAX(--SUBSTITUTE(_xlpm.endW,"W","")),IF(_xlpm.minW=_xlpm.maxW,"W"&_xlpm.minW,"W"&_xlpm.minW&"-"&"W"&_xlpm.maxW)))} -> W13-W15 | C18: {=SUMPRODUCT(--(TRIM('Task Tracker'!$B$8:$B$203)=TRIM($A18)),--('Task Tracker'!$D$8:$D$203<>""))} -> 6 | D18: {=SUMPRODUCT(--(TRIM('Task Tracker'!$B$8:$B$203)=TRIM($A18)),--(LEFT('Task Tracker'!$M$8:$M$203,9)="Completed"))} -> 0 | E18: {=SUMPRODUCT(--(TRIM('Task Tracker'!$B$8:$B$203)=TRIM($A18)),--('Task Tracker'!$M$8:$M$203="In Progress"))} -> 0 | F18: {=SUMPRODUCT(--(TRIM('Task Tracker'!$B$8:$B$203)=TRIM($A18)),--((('Task Tracker'!$M$8:$M$203="Not Started")+('Task Tracker'!$M$8:$M$203="Due to Start"))>0))} -> 6 | G18: {=IFERROR(SUMPRODUCT(--(TRIM('Task Tracker'!$B$8:$B$203)=TRIM($A18)),'Task Tracker'!$H$8:$H$203,'Task Tracker'!$N$8:$N$203)/SUMPRODUCT(--(TRIM('Task Tracker'!$B$8:$B$203)=TRIM($A18)),'Task Tracker'!$H$8:$H$203),0)} -> 0 | H18: {=IF(C18=0,"",IF(SUMPRODUCT(--(TRIM('Task Tracker'!$B$8:$B$203)=TRIM($A18)),--(LEFT('Task Tracker'!$M$8:$M$203,5)="Check"))>0,"Check Tracker",IF(D18=C18,"Complete",IF(SUMPRODUCT(--(TRIM('Task Tracker'!$B$8:$B$203)=TRIM($A18)),--('Task Tracker'!$M$8:$M$203="Delayed"))>0,"Delayed",IF(E18>0,"In Progress","Not Started")))))} -> Not Started | I18: {=IFERROR(MIN(_xlfn._xlws.FILTER('Task Tracker'!$I$8:$I$203,TRIM('Task Tracker'!$B$8:$B$203)=TRIM($A18))),"")} -> 46262 | J18: {=IFERROR(MAX(_xlfn._xlws.FILTER('Task Tracker'!$J$8:$J$203,TRIM('Task Tracker'!$B$8:$B$203)=TRIM($A18))),"")} -> 46274
A19: Reporting | B19: {=IF(C19=0,"",_xlfn.LET(_xlpm.startW,_xlfn._xlws.FILTER('Task Tracker'!$E$8:$E$203,(TRIM('Task Tracker'!$B$8:$B$203)=TRIM($A19))*('Task Tracker'!$E$8:$E$203<>"")),_xlpm.endW,_xlfn._xlws.FILTER('Task Tracker'!$F$8:$F$203,(TRIM('Task Tracker'!$B$8:$B$203)=TRIM($A19))*('Task Tracker'!$F$8:$F$203<>"")),_xlpm.minW,MIN(--SUBSTITUTE(_xlpm.startW,"W","")),_xlpm.maxW,MAX(--SUBSTITUTE(_xlpm.endW,"W","")),IF(_xlpm.minW=_xlpm.maxW,"W"&_xlpm.minW,"W"&_xlpm.minW&"-"&"W"&_xlpm.maxW)))} -> W15 | C19: {=SUMPRODUCT(--(TRIM('Task Tracker'!$B$8:$B$203)=TRIM($A19)),--('Task Tracker'!$D$8:$D$203<>""))} -> 2 | D19: {=SUMPRODUCT(--(TRIM('Task Tracker'!$B$8:$B$203)=TRIM($A19)),--(LEFT('Task Tracker'!$M$8:$M$203,9)="Completed"))} -> 0 | E19: {=SUMPRODUCT(--(TRIM('Task Tracker'!$B$8:$B$203)=TRIM($A19)),--('Task Tracker'!$M$8:$M$203="In Progress"))} -> 0 | F19: {=SUMPRODUCT(--(TRIM('Task Tracker'!$B$8:$B$203)=TRIM($A19)),--((('Task Tracker'!$M$8:$M$203="Not Started")+('Task Tracker'!$M$8:$M$203="Due to Start"))>0))} -> 2 | G19: {=IFERROR(SUMPRODUCT(--(TRIM('Task Tracker'!$B$8:$B$203)=TRIM($A19)),'Task Tracker'!$H$8:$H$203,'Task Tracker'!$N$8:$N$203)/SUMPRODUCT(--(TRIM('Task Tracker'!$B$8:$B$203)=TRIM($A19)),'Task Tracker'!$H$8:$H$203),0)} -> 0 | H19: {=IF(C19=0,"",IF(SUMPRODUCT(--(TRIM('Task Tracker'!$B$8:$B$203)=TRIM($A19)),--(LEFT('Task Tracker'!$M$8:$M$203,5)="Check"))>0,"Check Tracker",IF(D19=C19,"Complete",IF(SUMPRODUCT(--(TRIM('Task Tracker'!$B$8:$B$203)=TRIM($A19)),--('Task Tracker'!$M$8:$M$203="Delayed"))>0,"Delayed",IF(E19>0,"In Progress","Not Started")))))} -> Not Started | I19: {=IFERROR(MIN(_xlfn._xlws.FILTER('Task Tracker'!$I$8:$I$203,TRIM('Task Tracker'!$B$8:$B$203)=TRIM($A19))),"")} -> 46275 | J19: {=IFERROR(MAX(_xlfn._xlws.FILTER('Task Tracker'!$J$8:$J$203,TRIM('Task Tracker'!$B$8:$B$203)=TRIM($A19))),"")} -> 46276
A20: TOTAL | C20: =SUM(C12:C19) -> 36 | D20: =SUM(D12:D19) -> 2 | E20: =SUM(E12:E19) -> 0 | F20: =SUM(F12:F19) -> 33 | G20: =IFERROR(D20/C20,0) -> 0.055555556
A22: S
A23: Role | B23: Total Mandays Planned | C23: Mandays Used | D23: Remaining | E23: % Used
A24: UXR Lead | B24: {=SUMPRODUCT(ISNUMBER(SEARCH($A24,'Task Tracker'!$C$8:$C$203))*('Task Tracker'!$H$8:$H$203))} -> 57 | C24: {=SUMPRODUCT(ISNUMBER(SEARCH($A24,'Task Tracker'!$C$8:$C$203))*('Task Tracker'!$H$8:$H$203)*('Task Tracker'!$N$8:$N$203))} -> 17.92 | D24: =B24-C24 -> 39.08 | E24: =IFERROR(C24/B24,0) -> 0.31438596
A25: UXR Ast | B25: {=SUMPRODUCT(ISNUMBER(SEARCH($A25,'Task Tracker'!$C$8:$C$203))*('Task Tracker'!$H$8:$H$203))} -> 61 | C25: {=SUMPRODUCT(ISNUMBER(SEARCH($A25,'Task Tracker'!$C$8:$C$203))*('Task Tracker'!$H$8:$H$203)*('Task Tracker'!$N$8:$N$203))} -> 3 | D25: =C25-D25 -> 0 | E25: =IFERROR(C25/B25,0) -> 0.049180328
A26: Data Team | B26: {=SUMPRODUCT(ISNUMBER(SEARCH($A26,'Task Tracker'!$C$8:$C$203))*('Task Tracker'!$H$8:$H$203))} -> 10 | C26: {=SUMPRODUCT(ISNUMBER(SEARCH($A26,'Task Tracker'!$C$8:$C$203))*('Task Tracker'!$H$8:$H$203)*('Task Tracker'!$N$8:$N$203))} -> 0 | D26: =C26-D26 -> 0 | E26: =IFERROR(C26/B26,0) -> 0
A27: All (Total) | B27: =SUM(B24:B26) -> 128 | C27: =SUM(C24:C26) -> 20.92 | D27: =B27-C27 -> 107.08 | E27: =IFERROR(C27/B27,0) -> 0.1634375

Sheet Task Tracker
A1: KWSP i-Akaun UX Audit - Task Tracker
A7: # | B7: Workstream | C7: Owner | D7: Task / Deliverable | E7: Plan Start (Week) | F7: Plan End (Week) | G7: Task concurrency | H7: Mandays | I7: Plan Start | J7: Plan End | K7: Start Date | L7: Actual End | M7: Status | N7: % Complete | O7: Days Delayed | P7: Off days taken | Q7: Notes / Blockers | R7: URL Files
A8: 1 | B8: Setup | C8: UXR Lead | D8: Research Planning | E8: =IF(ISNUMBER(I8),"W"&MAX(0,INT((NETWORKDAYS(Dashboard!$B$3,I8,offday[Date])-1)/5)),"") -> W0 | F8: =IF(ISNUMBER(J8),"W"&MAX(0,INT((NETWORKDAYS(Dashboard!$B$3,J8,offday[Date])-1)/5)),"") -> W1 | H8: 8 | I8: =IF(H8="","",IF(ROW()=8,Dashboard!$B$3,IF(G8="",IFERROR(WORKDAY(J7,1,offday[Date]),"Check Predecessor"),IFERROR(WORKDAY(INDEX($J$8:$J$203,MATCH(G8,$A$8:$A$203,0)),1,offday[Date]),"Check Predecessor")))) -> 46148 | J8: =IF(H8="","",IF(ISNUMBER(I8),WORKDAY(I8,H8-1,offday[Date]),"Check Predecessor")) -> 46160 | K8: 46146 | L8: 46161 | M8: =IFERROR(IF(H8="","",IF(OR(NOT(ISNUMBER(I8)),NOT(ISNUMBER(J8))),"Check Plan",IF(AND(L8<>"",K8=""),"Check Actual Start",IF(AND(K8<>"",L8<>"",L8<K8),"Delayed",IF(AND(K8<>"",OR(L8="",L8>TODAY())),"In Progress",IF(L8<>"",IF(L8<J8,"Completed Early",IF(L8=J8,"Completed On Time","Delayed")),IF(TODAY()=I8,"Due to Start",IF(AND(I8>TODAY(),I8<=TODAY()+7),"Starts in "&(I8-TODAY())&" day"&IF((I8-TODAY())=1,"","s"),IF(TODAY()<I8,"Not Started","Delayed"))))))))),"Check Date") -> Delayed | N8: =IFERROR(IF(LEFT(M8,9)="Completed",1,IF(OR(M8="Not Started",M8="Due to Start"),0,IF(OR(M8="In Progress",M8="Delayed"),IF(K8="",0,MIN(0.99,NETWORKDAYS(K8,TODAY(),offday[Date])/MAX(1,NETWORKDAYS(K8,J8,offday[Date])))),0))),"") -> 0.99 | O8: =IFERROR(IF(NOT(ISNUMBER(J8)),"",IF(AND(L8<>"",ISNUMBER(L8),L8<=TODAY()),MAX(0,NETWORKDAYS(J8,L8,offday[Date])-1),IF(TODAY()>J8,MAX(0,NETWORKDAYS(J8,TODAY(),offday[Date])-1),"-"))),"-") -> 1 | P8: =IF(OR(NOT(ISNUMBER(I8)),NOT(ISNUMBER(J8))),"",(J8-I8+1)-NETWORKDAYS(I8,J8,offday[Date])) -> 5 | Q8: Pending Microservices list to shortlist - from data team
A9: 2 | B9: Setup | C9: UXR Lead | D9: HOS & HOD Approval on Research Plan | E9: =IF(ISNUMBER(I9),"W"&MAX(0,INT((NETWORKDAYS(Dashboard!$B$3,I9,offday[Date])-1)/5)),"") -> W1 | F9: =IF(ISNUMBER(J9),"W"&MAX(0,INT((NETWORKDAYS(Dashboard!$B$3,J9,offday[Date])-1)/5)),"") -> W2 | H9: 7 | I9: =IF(H9="","",IF(ROW()=8,Dashboard!$B$3,IF(G9="",IFERROR(WORKDAY(J8,1,offday[Date]),"Check Predecessor"),IFERROR(WORKDAY(INDEX($J$8:$J$203,MATCH(G9,$A$8:$A$203,0)),1,offday[Date]),"Check Predecessor")))) -> 46161 | J9: =IF(H9="","",IF(ISNUMBER(I9),WORKDAY(I9,H9-1,offday[Date]),"Check Predecessor")) -> 46176 | K9: 46164 | L9: 46168 | M9: =IFERROR(IF(H9="","",IF(OR(NOT(ISNUMBER(I9)),NOT(ISNUMBER(J9))),"Check Plan",IF(AND(L9<>"",K9=""),"Check Actual Start",IF(AND(K9<>"",L9<>"",L9<K9),"Delayed",IF(AND(K9<>"",OR(L9="",L9>TODAY())),"In Progress",IF(L9<>"",IF(L9<J9,"Completed Early",IF(L9=J9,"Completed On Time","Delayed")),IF(TODAY()=I9,"Due to Start",IF(AND(I9>TODAY(),I9<=TODAY()+7),"Starts in "&(I9-TODAY())&" day"&IF((I9-TODAY())=1,"","s"),IF(TODAY()<I9,"Not Started","Delayed"))))))))),"Check Date") -> Completed Early | N9: =IFERROR(IF(LEFT(M9,9)="Completed",1,IF(OR(M9="Not Started",M9="Due to Start"),0,IF(OR(M9="In Progress",M9="Delayed"),IF(K9="",0,MIN(0.99,NETWORKDAYS(K9,TODAY(),offday[Date])/MAX(1,NETWORKDAYS(K9,J9,offday[Date])))),0))),"") -> 1 | O9: =IFERROR(IF(NOT(ISNUMBER(J9)),"",IF(AND(L9<>"",ISNUMBER(L9),L9<=TODAY()),MAX(0,NETWORKDAYS(J9,L9,offday[Date])-1),IF(TODAY()>J9,MAX(0,NETWORKDAYS(J9,TODAY(),offday[Date])-1),"-"))),"-") -> 0 | P9: =IF(OR(NOT(ISNUMBER(I9)),NOT(ISNUMBER(J9))),"",(J9-I9+1)-NETWORKDAYS(I9,J9,offday[Date])) -> 9
A10: 3 | B10: Setup | C10: UXR Lead, UXR Ast | D10: Resource Hunting + Material Prep | E10: =IF(ISNUMBER(I10),"W"&MAX(0,INT((NETWORKDAYS(Dashboard!$B$3,I10,offday[Date])-1)/5)),"") -> W3 | F10: =IF(ISNUMBER(J10),"W"&MAX(0,INT((NETWORKDAYS(Dashboard!$B$3,J10,offday[Date])-1)/5)),"") -> W3 | H10: 3 | I10: =IF(H10="","",IF(ROW()=8,Dashboard!$B$3,IF(G10="",IFERROR(WORKDAY(J9,1,offday[Date]),"Check Predecessor"),IFERROR(WORKDAY(INDEX($J$8:$J$203,MATCH(G10,$A$8:$A$203,0)),1,offday[Date]),"Check Predecessor")))) -> 46177 | J10: =IF(H10="","",IF(ISNUMBER(I10),WORKDAY(I10,H10-1,offday[Date]),"Check Predecessor")) -> 46181 | K10: 46169 | L10: 46178 | M10: =IFERROR(IF(H10="","",IF(OR(NOT(ISNUMBER(I10)),NOT(ISNUMBER(J10))),"Check Plan",IF(AND(L10<>"",K10=""),"Check Actual Start",IF(AND(K10<>"",L10<>"",L10<K10),"Delayed",IF(AND(K10<>"",OR(L10="",L10>TODAY())),"In Progress",IF(L10<>"",IF(L10<J10,"Completed Early",IF(L10=J10,"Completed On Time","Delayed")),IF(TODAY()=I10,"Due to Start",IF(AND(I10>TODAY(),I10<=TODAY()+7),"Starts in "&(I10-TODAY())&" day"&IF((I10-TODAY())=1,"","s"),IF(TODAY()<I10,"Not Started","Delayed"))))))))),"Check Date") -> Completed Early | N10: =IFERROR(IF(LEFT(M10,9)="Completed",1,IF(OR(M10="Not Started",M10="Due to Start"),0,IF(OR(M10="In Progress",M10="Delayed"),IF(K10="",0,MIN(0.99,NETWORKDAYS(K10,TODAY(),offday[Date])/MAX(1,NETWORKDAYS(K10,J10,offday[Date])))),0))),"") -> 1 | O10: =IFERROR(IF(NOT(ISNUMBER(J10)),"",IF(AND(L10<>"",ISNUMBER(L10),L10<=TODAY()),MAX(0,NETWORKDAYS(J10,L10,offday[Date])-1),IF(TODAY()>J10,MAX(0,NETWORKDAYS(J10,TODAY(),offday[Date])-1),"-"))),"-") -> 0 | P10: =IF(OR(NOT(ISNUMBER(I10)),NOT(ISNUMBER(J10))),"",(J10-I10+1)-NETWORKDAYS(I10,J10,offday[Date])) -> 2 | Q10: Faz send email to all HOU > Suvi follow-up
A11: 4 | B11: Checkpoint | C11: UXR Lead, UXR Ast | D11: Debriefing to working team + assimilation | E11: =IF(ISNUMBER(I11),"W"&MAX(0,INT((NETWORKDAYS(Dashboard!$B$3,I11,offday[Date])-1)/5)),"") -> W3 | F11: =IF(ISNUMBER(J11),"W"&MAX(0,INT((NETWORKDAYS(Dashboard!$B$3,J11,offday[Date])-1)/5)),"") -> W4 | H11: 3 | I11: =IF(H11="","",IF(ROW()=8,Dashboard!$B$3,IF(G11="",IFERROR(WORKDAY(J10,1,offday[Date]),"Check Predecessor"),IFERROR(WORKDAY(INDEX($J$8:$J$203,MATCH(G11,$A$8:$A$203,0)),1,offday[Date]),"Check Predecessor")))) -> 46182 | J11: =IF(H11="","",IF(ISNUMBER(I11),WORKDAY(I11,H11-1,offday[Date]),"Check Predecessor")) -> 46190 | M11: =IFERROR(IF(H11="","",IF(OR(NOT(ISNUMBER(I11)),NOT(ISNUMBER(J11))),"Check Plan",IF(AND(L11<>"",K11=""),"Check Actual Start",IF(AND(K11<>"",L11<>"",L11<K11),"Delayed",IF(AND(K11<>"",OR(L11="",L11>TODAY())),"In Progress",IF(L11<>"",IF(L11<J11,"Completed Early",IF(L11=J11,"Completed On Time","Delayed")),IF(TODAY()=I11,"Due to Start",IF(AND(I11>TODAY(),I11<=TODAY()+7),"Starts in "&(I11-TODAY())&" day"&IF((I11-TODAY())=1,"","s"),IF(TODAY()<I11,"Not Started","Delayed"))))))))),"Check Date") -> Starts in 1 day | N11: =IFERROR(IF(LEFT(M11,9)="Completed",1,IF(OR(M11="Not Started",M11="Due to Start"),0,IF(OR(M11="In Progress",M11="Delayed"),IF(K11="",0,MIN(0.99,NETWORKDAYS(K11,TODAY(),offday[Date])/MAX(1,NETWORKDAYS(K11,J11,offday[Date])))),0))),"") -> 0 | O11: =IFERROR(IF(NOT(ISNUMBER(J11)),"",IF(AND(L11<>"",ISNUMBER(L11),L11<=TODAY()),MAX(0,NETWORKDAYS(J11,L11,offday[Date])-1),IF(TODAY()>J11,MAX(0,NETWORKDAYS(J11,TODAY(),offday[Date])-1),"-"))),"-") -> - | P11: =IF(OR(NOT(ISNUMBER(I11)),NOT(ISNUMBER(J11))),"",(J11-I11+1)-NETWORKDAYS(I11,J11,offday[Date])) -> 6
A12: 5 | B12: Setup | C12: UXR Lead | D12: Request RCM + IM Data | E12: =IF(ISNUMBER(I12),"W"&MAX(0,INT((NETWORKDAYS(Dashboard!$B$3,I12,offday[Date])-1)/5)),"") -> W4 | F12: =IF(ISNUMBER(J12),"W"&MAX(0,INT((NETWORKDAYS(Dashboard!$B$3,J12,offday[Date])-1)/5)),"") -> W4 | H12: 3 | I12: =IF(H12="","",IF(ROW()=8,Dashboard!$B$3,IF(G12="",IFERROR(WORKDAY(J11,1,offday[Date]),"Check Predecessor"),IFERROR(WORKDAY(INDEX($J$8:$J$203,MATCH(G12,$A$8:$A$203,0)),1,offday[Date]),"Check Predecessor")))) -> 46191 | J12: =IF(H12="","",IF(ISNUMBER(I12),WORKDAY(I12,H12-1,offday[Date]),"Check Predecessor")) -> 46195 | M12: =IFERROR(IF(H12="","",IF(OR(NOT(ISNUMBER(I12)),NOT(ISNUMBER(J12))),"Check Plan",IF(AND(L12<>"",K12=""),"Check Actual Start",IF(AND(K12<>"",L12<>"",L12<K12),"Delayed",IF(AND(K12<>"",OR(L12="",L12>TODAY())),"In Progress",IF(L12<>"",IF(L12<J12,"Completed Early",IF(L12=J12,"Completed On Time","Delayed")),IF(TODAY()=I12,"Due to Start",IF(AND(I12>TODAY(),I12<=TODAY()+7),"Starts in "&(I12-TODAY())&" day"&IF((I12-TODAY())=1,"","s"),IF(TODAY()<I12,"Not Started","Delayed"))))))))),"Check Date") -> Not Started | N12: =IFERROR(IF(LEFT(M12,9)="Completed",1,IF(OR(M12="Not Started",M12="Due to Start"),0,IF(OR(M12="In Progress",M12="Delayed"),IF(K12="",0,MIN(0.99,NETWORKDAYS(K12,TODAY(),offday[Date])/MAX(1,NETWORKDAYS(K12,J12,offday[Date])))),0))),"") -> 0 | O12: =IFERROR(IF(NOT(ISNUMBER(J12)),"",IF(AND(L12<>"",ISNUMBER(L12),L12<=TODAY()),MAX(0,NETWORKDAYS(J12,L12,offday[Date])-1),IF(TODAY()>J12,MAX(0,NETWORKDAYS(J12,TODAY(),offday[Date])-1),"-"))),"-") -> - | P12: =IF(OR(NOT(ISNUMBER(I12)),NOT(ISNUMBER(J12))),"",(J12-I12+1)-NETWORKDAYS(I12,J12,offday[Date])) -> 2 | Q12: Pn Zanita / Pn Jamilah
A13: 6 | B13: Setup | C13: UXR Lead | D13: RCM + Data Analysis | E13: =IF(ISNUMBER(I13),"W"&MAX(0,INT((NETWORKDAYS(Dashboard!$B$3,I13,offday[Date])-1)/5)),"") -> W4 | F13: =IF(ISNUMBER(J13),"W"&MAX(0,INT((NETWORKDAYS(Dashboard!$B$3,J13,offday[Date])-1)/5)),"") -> W4 | G13: 4 | H13: 2 | I13: =IF(H13="","",IF(ROW()=8,Dashboard!$B$3,IF(G13="",IFERROR(WORKDAY(J12,1,offday[Date]),"Check Predecessor"),IFERROR(WORKDAY(INDEX($J$8:$J$203,MATCH(G13,$A$8:$A$203,0)),1,offday[Date]),"Check Predecessor")))) -> 46191 | J13: =IF(H13="","",IF(ISNUMBER(I13),WORKDAY(I13,H13-1,offday[Date]),"Check Predecessor")) -> 46192 | M13: =IFERROR(IF(H13="","",IF(OR(NOT(ISNUMBER(I13)),NOT(ISNUMBER(J13))),"Check Plan",IF(AND(L13<>"",K13=""),"Check Actual Start",IF(AND(K13<>"",L13<>"",L13<K13),"Delayed",IF(AND(K13<>"",OR(L13="",L13>TODAY())),"In Progress",IF(L13<>"",IF(L13<J13,"Completed Early",IF(L13=J13,"Completed On Time","Delayed")),IF(TODAY()=I13,"Due to Start",IF(AND(I13>TODAY(),I13<=TODAY()+7),"Starts in "&(I13-TODAY())&" day"&IF((I13-TODAY())=1,"","s"),IF(TODAY()<I13,"Not Started","Delayed"))))))))),"Check Date") -> Not Started | N13: =IFERROR(IF(LEFT(M13,9)="Completed",1,IF(OR(M13="Not Started",M13="Due to Start"),0,IF(OR(M13="In Progress",M13="Delayed"),IF(K13="",0,MIN(0.99,NETWORKDAYS(K13,TODAY(),offday[Date])/MAX(1,NETWORKDAYS(K13,J13,offday[Date])))),0))),"") -> 0 | O13: =IFERROR(IF(NOT(ISNUMBER(J13)),"",IF(AND(L13<>"",ISNUMBER(L13),L13<=TODAY()),MAX(0,NETWORKDAYS(J13,L13,offday[Date])-1),IF(TODAY()>J13,MAX(0,NETWORKDAYS(J13,TODAY(),offday[Date])-1),"-"))),"-") -> - | P13: =IF(OR(NOT(ISNUMBER(I13)),NOT(ISNUMBER(J13))),"",(J13-I13+1)-NETWORKDAYS(I13,J13,offday[Date])) -> 0 | Q13: Faizul Azhair
A14: 7 | B14: Heuristics Study | C14: UXR Ast | D14: Conduct Nielsen's 10 Usability Heuristics | E14: =IF(ISNUMBER(I14),"W"&MAX(0,INT((NETWORKDAYS(Dashboard!$B$3,I14,offday[Date])-1)/5)),"") -> W4 | F14: =IF(ISNUMBER(J14),"W"&MAX(0,INT((NETWORKDAYS(Dashboard!$B$3,J14,offday[Date])-1)/5)),"") -> W5 | G14: 4 | H14: 5 | I14: =IF(H14="","",IF(ROW()=8,Dashboard!$B$3,IF(G14="",IFERROR(WORKDAY(J13,1,offday[Date]),"Check Predecessor"),IFERROR(WORKDAY(INDEX($J$8:$J$203,MATCH(G14,$A$8:$A$203,0)),1,offday[Date]),"Check Predecessor")))) -> 46191 | J14: =IF(H14="","",IF(ISNUMBER(I14),WORKDAY(I14,H14-1,offday[Date]),"Check Predecessor")) -> 46202 | M14: =IFERROR(IF(H14="","",IF(OR(NOT(ISNUMBER(I14)),NOT(ISNUMBER(J14))),"Check Plan",IF(AND(L14<>"",K14=""),"Check Actual Start",IF(AND(K14<>"",L14<>"",L14<K14),"Delayed",IF(AND(K14<>"",OR(L14="",L14>TODAY())),"In Progress",IF(L14<>"",IF(L14<J14,"Completed Early",IF(L14=J14,"Completed On Time","Delayed")),IF(TODAY()=I14,"Due to Start",IF(AND(I14>TODAY(),I14<=TODAY()+7),"Starts in "&(I14-TODAY())&" day"&IF((I14-TODAY())=1,"","s"),IF(TODAY()<I14,"Not Started","Delayed"))))))))),"Check Date") -> Not Started | N14: =IFERROR(IF(LEFT(M14,9)="Completed",1,IF(OR(M14="Not Started",M14="Due to Start"),0,IF(OR(M14="In Progress",M14="Delayed"),IF(K14="",0,MIN(0.99,NETWORKDAYS(K14,TODAY(),offday[Date])/MAX(1,NETWORKDAYS(K14,J14,offday[Date])))),0))),"") -> 0 | O14: =IFERROR(IF(NOT(ISNUMBER(J14)),"",IF(AND(L14<>"",ISNUMBER(L14),L14<=TODAY()),MAX(0,NETWORKDAYS(J14,L14,offday[Date])-1),IF(TODAY()>J14,MAX(0,NETWORKDAYS(J14,TODAY(),offday[Date])-1),"-"))),"-") -> - | P14: =IF(OR(NOT(ISNUMBER(I14)),NOT(ISNUMBER(J14))),"",(J14-I14+1)-NETWORKDAYS(I14,J14,offday[Date])) -> 7
A15: 8 | B15: Heuristics Study | C15: UXR Ast | D15: Conduct Mobile-specific usability principles | E15: =IF(ISNUMBER(I15),"W"&MAX(0,INT((NETWORKDAYS(Dashboard!$B$3,I15,offday[Date])-1)/5)),"") -> W5 | F15: =IF(ISNUMBER(J15),"W"&MAX(0,INT((NETWORKDAYS(Dashboard!$B$3,J15,offday[Date])-1)/5)),"") -> W5 | H15: 2 | I15: =IF(H15="","",IF(ROW()=8,Dashboard!$B$3,IF(G15="",IFERROR(WORKDAY(J14,1,offday[Date]),"Check Predecessor"),IFERROR(WORKDAY(INDEX($J$8:$J$203,MATCH(G15,$A$8:$A$203,0)),1,offday[Date]),"Check Predecessor")))) -> 46203 | J15: =IF(H15="","",IF(ISNUMBER(I15),WORKDAY(I15,H15-1,offday[Date]),"Check Predecessor")) -> 46204 | M15: =IFERROR(IF(H15="","",IF(OR(NOT(ISNUMBER(I15)),NOT(ISNUMBER(J15))),"Check Plan",IF(AND(L15<>"",K15=""),"Check Actual Start",IF(AND(K15<>"",L15<>"",L15<K15),"Delayed",IF(AND(K15<>"",OR(L15="",L15>TODAY())),"In Progress",IF(L15<>"",IF(L15<J15,"Completed Early",IF(L15=J15,"Completed On Time","Delayed")),IF(TODAY()=I15,"Due to Start",IF(AND(I15>TODAY(),I15<=TODAY()+7),"Starts in "&(I15-TODAY())&" day"&IF((I15-TODAY())=1,"","s"),IF(TODAY()<I15,"Not Started","Delayed"))))))))),"Check Date") -> Not Started | N15: =IFERROR(IF(LEFT(M15,9)="Completed",1,IF(OR(M15="Not Started",M15="Due to Start"),0,IF(OR(M15="In Progress",M15="Delayed"),IF(K15="",0,MIN(0.99,NETWORKDAYS(K15,TODAY(),offday[Date])/MAX(1,NETWORKDAYS(K15,J15,offday[Date])))),0))),"") -> 0 | O15: =IFERROR(IF(NOT(ISNUMBER(J15)),"",IF(AND(L15<>"",ISNUMBER(L15),L15<=TODAY()),MAX(0,NETWORKDAYS(J15,L15,offday[Date])-1),IF(TODAY()>J15,MAX(0,NETWORKDAYS(J15,TODAY(),offday[Date])-1),"-"))),"-") -> - | P15: =IF(OR(NOT(ISNUMBER(I15)),NOT(ISNUMBER(J15))),"",(J15-I15+1)-NETWORKDAYS(I15,J15,offday[Date])) -> 0 | Q15: Touch targets, gestures, orientation, loading states, offline behaviour
A16: 9 | B16: Heuristics Study | C16: UXR Ast | D16: Conduct app trust & security standards | E16: =IF(ISNUMBER(I16),"W"&MAX(0,INT((NETWORKDAYS(Dashboard!$B$3,I16,offday[Date])-1)/5)),"") -> W5 | F16: =IF(ISNUMBER(J16),"W"&MAX(0,INT((NETWORKDAYS(Dashboard!$B$3,J16,offday[Date])-1)/5)),"") -> W5 | H16: 1 | I16: =IF(H16="","",IF(ROW()=8,Dashboard!$B$3,IF(G16="",IFERROR(WORKDAY(J15,1,offday[Date]),"Check Predecessor"),IFERROR(WORKDAY(INDEX($J$8:$J$203,MATCH(G16,$A$8:$A$203,0)),1,offday[Date]),"Check Predecessor")))) -> 46205 | J16: =IF(H16="","",IF(ISNUMBER(I16),WORKDAY(I16,H16-1,offday[Date]),"Check Predecessor")) -> 46205 | M16: =IFERROR(IF(H16="","",IF(OR(NOT(ISNUMBER(I16)),NOT(ISNUMBER(J16))),"Check Plan",IF(AND(L16<>"",K16=""),"Check Actual Start",IF(AND(K16<>"",L16<>"",L16<K16),"Delayed",IF(AND(K16<>"",OR(L16="",L16>TODAY())),"In Progress",IF(L16<>"",IF(L16<J16,"Completed Early",IF(L16=J16,"Completed On Time","Delayed")),IF(TODAY()=I16,"Due to Start",IF(AND(I16>TODAY(),I16<=TODAY()+7),"Starts in "&(I16-TODAY())&" day"&IF((I16-TODAY())=1,"","s"),IF(TODAY()<I16,"Not Started","Delayed"))))))))),"Check Date") -> Not Started | N16: =IFERROR(IF(LEFT(M16,9)="Completed",1,IF(OR(M16="Not Started",M16="Due to Start"),0,IF(OR(M16="In Progress",M16="Delayed"),IF(K16="",0,MIN(0.99,NETWORKDAYS(K16,TODAY(),offday[Date])/MAX(1,NETWORKDAYS(K16,J16,offday[Date])))),0))),"") -> 0 | O16: =IFERROR(IF(NOT(ISNUMBER(J16)),"",IF(AND(L16<>"",ISNUMBER(L16),L16<=TODAY()),MAX(0,NETWORKDAYS(J16,L16,offday[Date])-1),IF(TODAY()>J16,MAX(0,NETWORKDAYS(J16,TODAY(),offday[Date])-1),"-"))),"-") -> - | P16: =IF(OR(NOT(ISNUMBER(I16)),NOT(ISNUMBER(J16))),"",(J16-I16+1)-NETWORKDAYS(I16,J16,offday[Date])) -> 0 | Q16: Custom checklist — error messaging, confirmations, transparency
A17: 10 | B17: Heuristics Study | C17: UXR Ast | D17: Conduct WCAG 2.1 AA accessibility compliance | E17: =IF(ISNUMBER(I17),"W"&MAX(0,INT((NETWORKDAYS(Dashboard!$B$3,I17,offday[Date])-1)/5)),"") -> W5 | F17: =IF(ISNUMBER(J17),"W"&MAX(0,INT((NETWORKDAYS(Dashboard!$B$3,J17,offday[Date])-1)/5)),"") -> W5 | H17: 1 | I17: =IF(H17="","",IF(ROW()=8,Dashboard!$B$3,IF(G17="",IFERROR(WORKDAY(J16,1,offday[Date]),"Check Predecessor"),IFERROR(WORKDAY(INDEX($J$8:$J$203,MATCH(G17,$A$8:$A$203,0)),1,offday[Date]),"Check Predecessor")))) -> 46206 | J17: =IF(H17="","",IF(ISNUMBER(I17),WORKDAY(I17,H17-1,offday[Date]),"Check Predecessor")) -> 46206 | M17: =IFERROR(IF(H17="","",IF(OR(NOT(ISNUMBER(I17)),NOT(ISNUMBER(J17))),"Check Plan",IF(AND(L17<>"",K17=""),"Check Actual Start",IF(AND(K17<>"",L17<>"",L17<K17),"Delayed",IF(AND(K17<>"",OR(L17="",L17>TODAY())),"In Progress",IF(L17<>"",IF(L17<J17,"Completed Early",IF(L17=J17,"Completed On Time","Delayed")),IF(TODAY()=I17,"Due to Start",IF(AND(I17>TODAY(),I17<=TODAY()+7),"Starts in "&(I17-TODAY())&" day"&IF((I17-TODAY())=1,"","s"),IF(TODAY()<I17,"Not Started","Delayed"))))))))),"Check Date") -> Not Started | N17: =IFERROR(IF(LEFT(M17,9)="Completed",1,IF(OR(M17="Not Started",M17="Due to Start"),0,IF(OR(M17="In Progress",M17="Delayed"),IF(K17="",0,MIN(0.99,NETWORKDAYS(K17,TODAY(),offday[Date])/MAX(1,NETWORKDAYS(K17,J17,offday[Date])))),0))),"") -> 0 | O17: =IFERROR(IF(NOT(ISNUMBER(J17)),"",IF(AND(L17<>"",ISNUMBER(L17),L17<=TODAY()),MAX(0,NETWORKDAYS(J17,L17,offday[Date])-1),IF(TODAY()>J17,MAX(0,NETWORKDAYS(J17,TODAY(),offday[Date])-1),"-"))),"-") -> - | P17: =IF(OR(NOT(ISNUMBER(I17)),NOT(ISNUMBER(J17))),"",(J17-I17+1)-NETWORKDAYS(I17,J17,offday[Date])) -> 0 | Q17: Automated tools (axe, WAVE) + manual walkthrough with screen readers. Benchmark with other apps. Population affected. Special case for security: password for blind people how secure if read out
A18: 11 | B18: Heuristics Study | C18: UXR Ast/Content | D18: Conduct Content & language clarity | E18: =IF(ISNUMBER(I18),"W"&MAX(0,INT((NETWORKDAYS(Dashboard!$B$3,I18,offday[Date])-1)/5)),"") -> W6 | F18: =IF(ISNUMBER(J18),"W"&MAX(0,INT((NETWORKDAYS(Dashboard!$B$3,J18,offday[Date])-1)/5)),"") -> W6 | H18: 2 | I18: =IF(H18="","",IF(ROW()=8,Dashboard!$B$3,IF(G18="",IFERROR(WORKDAY(J17,1,offday[Date]),"Check Predecessor"),IFERROR(WORKDAY(INDEX($J$8:$J$203,MATCH(G18,$A$8:$A$203,0)),1,offday[Date]),"Check Predecessor")))) -> 46209 | J18: =IF(H18="","",IF(ISNUMBER(I18),WORKDAY(I18,H18-1,offday[Date]),"Check Predecessor")) -> 46210 | M18: =IFERROR(IF(H18="","",IF(OR(NOT(ISNUMBER(I18)),NOT(ISNUMBER(J18))),"Check Plan",IF(AND(L18<>"",K18=""),"Check Actual Start",IF(AND(K18<>"",L18<>"",L18<K18),"Delayed",IF(AND(K18<>"",OR(L18="",L18>TODAY())),"In Progress",IF(L18<>"",IF(L18<J18,"Completed Early",IF(L18=J18,"Completed On Time","Delayed")),IF(TODAY()=I18,"Due to Start",IF(AND(I18>TODAY(),I18<=TODAY()+7),"Starts in "&(I18-TODAY())&" day"&IF((I18-TODAY())=1,"","s"),IF(TODAY()<I18,"Not Started","Delayed"))))))))),"Check Date") -> Not Started | N18: =IFERROR(IF(LEFT(M18,9)="Completed",1,IF(OR(M18="Not Started",M18="Due to Start"),0,IF(OR(M18="In Progress",M18="Delayed"),IF(K18="",0,MIN(0.99,NETWORKDAYS(K18,TODAY(),offday[Date])/MAX(1,NETWORKDAYS(K18,J18,offday[Date])))),0))),"") -> 0 | O18: =IFERROR(IF(NOT(ISNUMBER(J18)),"",IF(AND(L18<>"",ISNUMBER(L18),L18<=TODAY()),MAX(0,NETWORKDAYS(J18,L18,offday[Date])-1),IF(TODAY()>J18,MAX(0,NETWORKDAYS(J18,TODAY(),offday[Date])-1),"-"))),"-") -> - | P18: =IF(OR(NOT(ISNUMBER(I18)),NOT(ISNUMBER(J18))),"",(J18-I18+1)-NETWORKDAYS(I18,J18,offday[Date])) -> 0 | Q18: Tone, reading level, multi-language quality across all screens
A19: 12 | B19: Heuristics Study | C19: UXR Ast/UIUX | D19: Conduct Design consistency audit | E19: =IF(ISNUMBER(I19),"W"&MAX(0,INT((NETWORKDAYS(Dashboard!$B$3,I19,offday[Date])-1)/5)),"") -> W6 | F19: =IF(ISNUMBER(J19),"W"&MAX(0,INT((NETWORKDAYS(Dashboard!$B$3,J19,offday[Date])-1)/5)),"") -> W7 | H19: 4 | I19: =IF(H19="","",IF(ROW()=8,Dashboard!$B$3,IF(G19="",IFERROR(WORKDAY(J18,1,offday[Date]),"Check Predecessor"),IFERROR(WORKDAY(INDEX($J$8:$J$203,MATCH(G19,$A$8:$A$203,0)),1,offday[Date]),"Check Predecessor")))) -> 46211 | J19: =IF(H19="","",IF(ISNUMBER(I19),WORKDAY(I19,H19-1,offday[Date]),"Check Predecessor")) -> 46216 | M19: =IFERROR(IF(H19="","",IF(OR(NOT(ISNUMBER(I19)),NOT(ISNUMBER(J19))),"Check Plan",IF(AND(L19<>"",K19=""),"Check Actual Start",IF(AND(K19<>"",L19<>"",L19<K19),"Delayed",IF(AND(K19<>"",OR(L19="",L19>TODAY())),"In Progress",IF(L19<>"",IF(L19<J19,"Completed Early",IF(L19=J19,"Completed On Time","Delayed")),IF(TODAY()=I19,"Due to Start",IF(AND(I19>TODAY(),I19<=TODAY()+7),"Starts in "&(I19-TODAY())&" day"&IF((I19-TODAY())=1,"","s"),IF(TODAY()<I19,"Not Started","Delayed"))))))))),"Check Date") -> Not Started | N19: =IFERROR(IF(LEFT(M19,9)="Completed",1,IF(OR(M19="Not Started",M19="Due to Start"),0,IF(OR(M19="In Progress",M19="Delayed"),IF(K19="",0,MIN(0.99,NETWORKDAYS(K19,TODAY(),offday[Date])/MAX(1,NETWORKDAYS(K19,J19,offday[Date])))),0))),"") -> 0 | O19: =IFERROR(IF(NOT(ISNUMBER(J19)),"",IF(AND(L19<>"",ISNUMBER(L19),L19<=TODAY()),MAX(0,NETWORKDAYS(J19,L19,offday[Date])-1),IF(TODAY()>J19,MAX(0,NETWORKDAYS(J19,TODAY(),offday[Date])-1),"-"))),"-") -> - | P19: =IF(OR(NOT(ISNUMBER(I19)),NOT(ISNUMBER(J19))),"",(J19-I19+1)-NETWORKDAYS(I19,J19,offday[Date])) -> 2 | Q19: UI patterns, spacing, typography, iconography
A20: 13 | B20: Analytics Review | C20: Data Team | D20: Conduct In-app analytics | E20: =IF(ISNUMBER(I20),"W"&MAX(0,INT((NETWORKDAYS(Dashboard!$B$3,I20,offday[Date])-1)/5)),"") -> W4 | F20: =IF(ISNUMBER(J20),"W"&MAX(0,INT((NETWORKDAYS(Dashboard!$B$3,J20,offday[Date])-1)/5)),"") -> W4 | G20: 4 | H20: 4 | I20: =IF(H20="","",IF(ROW()=8,Dashboard!$B$3,IF(G20="",IFERROR(WORKDAY(J19,1,offday[Date]),"Check Predecessor"),IFERROR(WORKDAY(INDEX($J$8:$J$203,MATCH(G20,$A$8:$A$203,0)),1,offday[Date]),"Check Predecessor")))) -> 46191 | J20: =IF(H20="","",IF(ISNUMBER(I20),WORKDAY(I20,H20-1,offday[Date]),"Check Predecessor")) -> 46196 | M20: =IFERROR(IF(H20="","",IF(OR(NOT(ISNUMBER(I20)),NOT(ISNUMBER(J20))),"Check Plan",IF(AND(L20<>"",K20=""),"Check Actual Start",IF(AND(K20<>"",L20<>"",L20<K20),"Delayed",IF(AND(K20<>"",OR(L20="",L20>TODAY())),"In Progress",IF(L20<>"",IF(L20<J20,"Completed Early",IF(L20=J20,"Completed On Time","Delayed")),IF(TODAY()=I20,"Due to Start",IF(AND(I20>TODAY(),I20<=TODAY()+7),"Starts in "&(I20-TODAY())&" day"&IF((I20-TODAY())=1,"","s"),IF(TODAY()<I20,"Not Started","Delayed"))))))))),"Check Date") -> Not Started | N20: =IFERROR(IF(LEFT(M20,9)="Completed",1,IF(OR(M20="Not Started",M20="Due to Start"),0,IF(OR(M20="In Progress",M20="Delayed"),IF(K20="",0,MIN(0.99,NETWORKDAYS(K20,TODAY(),offday[Date])/MAX(1,NETWORKDAYS(K20,J20,offday[Date])))),0))),"") -> 0 | O20: =IFERROR(IF(NOT(ISNUMBER(J20)),"",IF(AND(L20<>"",ISNUMBER(L20),L20<=TODAY()),MAX(0,NETWORKDAYS(J20,L20,offday[Date])-1),IF(TODAY()>J20,MAX(0,NETWORKDAYS(J20,TODAY(),offday[Date])-1),"-"))),"-") -> - | P20: =IF(OR(NOT(ISNUMBER(I20)),NOT(ISNUMBER(J20))),"",(J20-I20+1)-NETWORKDAYS(I20,J20,offday[Date])) -> 2 | Q20: User profile, overview
A21: 14 | B21: Analytics Review | C21: Data Team | D21: Conduct Drop-off / funnel analysis | E21: =IF(ISNUMBER(I21),"W"&MAX(0,INT((NETWORKDAYS(Dashboard!$B$3,I21,offday[Date])-1)/5)),"") -> W5 | F21: =IF(ISNUMBER(J21),"W"&MAX(0,INT((NETWORKDAYS(Dashboard!$B$3,J21,offday[Date])-1)/5)),"") -> W5 | H21: 4 | I21: =IF(H21="","",IF(ROW()=8,Dashboard!$B$3,IF(G21="",IFERROR(WORKDAY(J20,1,offday[Date]),"Check Predecessor"),IFERROR(WORKDAY(INDEX($J$8:$J$203,MATCH(G21,$A$8:$A$203,0)),1,offday[Date]),"Check Predecessor")))) -> 46202 | J21: =IF(H21="","",IF(ISNUMBER(I21),WORKDAY(I21,H21-1,offday[Date]),"Check Predecessor")) -> 46205 | M21: =IFERROR(IF(H21="","",IF(OR(NOT(ISNUMBER(I21)),NOT(ISNUMBER(J21))),"Check Plan",IF(AND(L21<>"",K21=""),"Check Actual Start",IF(AND(K21<>"",L21<>"",L21<K21),"Delayed",IF(AND(K21<>"",OR(L21="",L21>TODAY())),"In Progress",IF(L21<>"",IF(L21<J21,"Completed Early",IF(L21=J21,"Completed On Time","Delayed")),IF(TODAY()=I21,"Due to Start",IF(AND(I21>TODAY(),I21<=TODAY()+7),"Starts in "&(I21-TODAY())&" day"&IF((I21-TODAY())=1,"","s"),IF(TODAY()<I21,"Not Started","Delayed"))))))))),"Check Date") -> Not Started | N21: =IFERROR(IF(LEFT(M21,9)="Completed",1,IF(OR(M21="Not Started",M21="Due to Start"),0,IF(OR(M21="In Progress",M21="Delayed"),IF(K21="",0,MIN(0.99,NETWORKDAYS(K21,TODAY(),offday[Date])/MAX(1,NETWORKDAYS(K21,J21,offday[Date])))),0))),"") -> 0 | O21: =IFERROR(IF(NOT(ISNUMBER(J21)),"",IF(AND(L21<>"",ISNUMBER(L21),L21<=TODAY()),MAX(0,NETWORKDAYS(J21,L21,offday[Date])-1),IF(TODAY()>J21,MAX(0,NETWORKDAYS(J21,TODAY(),offday[Date])-1),"-"))),"-") -> - | P21: =IF(OR(NOT(ISNUMBER(I21)),NOT(ISNUMBER(J21))),"",(J21-I21+1)-NETWORKDAYS(I21,J21,offday[Date])) -> 0
A22: 15 | B22: Analytics Review | C22: Data Team | D22: Conduct App crash and error reports | E22: =IF(ISNUMBER(I22),"W"&MAX(0,INT((NETWORKDAYS(Dashboard!$B$3,I22,offday[Date])-1)/5)),"") -> W5 | F22: =IF(ISNUMBER(J22),"W"&MAX(0,INT((NETWORKDAYS(Dashboard!$B$3,J22,offday[Date])-1)/5)),"") -> W6 | H22: 2 | I22: =IF(H22="","",IF(ROW()=8,Dashboard!$B$3,IF(G22="",IFERROR(WORKDAY(J21,1,offday[Date]),"Check Predecessor"),IFERROR(WORKDAY(INDEX($J$8:$J$203,MATCH(G22,$A$8:$A$203,0)),1,offday[Date]),"Check Predecessor")))) -> 46206 | J22: =IF(H22="","",IF(ISNUMBER(I22),WORKDAY(I22,H22-1,offday[Date]),"Check Predecessor")) -> 46209 | M22: =IFERROR(IF(H22="","",IF(OR(NOT(ISNUMBER(I22)),NOT(ISNUMBER(J22))),"Check Plan",IF(AND(L22<>"",K22=""),"Check Actual Start",IF(AND(K22<>"",L22<>"",L22<K22),"Delayed",IF(AND(K22<>"",OR(L22="",L22>TODAY())),"In Progress",IF(L22<>"",IF(L22<J22,"Completed Early",IF(L22=J22,"Completed On Time","Delayed")),IF(TODAY()=I22,"Due to Start",IF(AND(I22>TODAY(),I22<=TODAY()+7),"Starts in "&(I22-TODAY())&" day"&IF((I22-TODAY())=1,"","s"),IF(TODAY()<I22,"Not Started","Delayed"))))))))),"Check Date") -> Not Started | N22: =IFERROR(IF(LEFT(M22,9)="Completed",1,IF(OR(M22="Not Started",M22="Due to Start"),0,IF(OR(M22="In Progress",M22="Delayed"),IF(K22="",0,MIN(0.99,NETWORKDAYS(K22,TODAY(),offday[Date])/MAX(1,NETWORKDAYS(K22,J22,offday[Date])))),0))),"") -> 0 | O22: =IFERROR(IF(NOT(ISNUMBER(J22)),"",IF(AND(L22<>"",ISNUMBER(L22),L22<=TODAY()),MAX(0,NETWORKDAYS(J22,L22,offday[Date])-1),IF(TODAY()>J22,MAX(0,NETWORKDAYS(J22,TODAY(),offday[Date])-1),"-"))),"-") -> - | P22: =IF(OR(NOT(ISNUMBER(I22)),NOT(ISNUMBER(J22))),"",(J22-I22+1)-NETWORKDAYS(I22,J22,offday[Date])) -> 2
A23: 16 | B23: Benchmarking and Peer Study | C23: UXR Lead | D23: Conduct Competitive Benchmarking | E23: =IF(ISNUMBER(I23),"W"&MAX(0,INT((NETWORKDAYS(Dashboard!$B$3,I23,offday[Date])-1)/5)),"") -> W4 | F23: =IF(ISNUMBER(J23),"W"&MAX(0,INT((NETWORKDAYS(Dashboard!$B$3,J23,offday[Date])-1)/5)),"") -> W5 | G23: 4 | H23: 7 | I23: =IF(H23="","",IF(ROW()=8,Dashboard!$B$3,IF(G23="",IFERROR(WORKDAY(J22,1,offday[Date]),"Check Predecessor"),IFERROR(WORKDAY(INDEX($J$8:$J$203,MATCH(G23,$A$8:$A$203,0)),1,offday[Date]),"Check Predecessor")))) -> 46191 | J23: =IF(H23="","",IF(ISNUMBER(I23),WORKDAY(I23,H23-1,offday[Date]),"Check Predecessor")) -> 46204 | M23: =IFERROR(IF(H23="","",IF(OR(NOT(ISNUMBER(I23)),NOT(ISNUMBER(J23))),"Check Plan",IF(AND(L23<>"",K23=""),"Check Actual Start",IF(AND(K23<>"",L23<>"",L23<K23),"Delayed",IF(AND(K23<>"",OR(L23="",L23>TODAY())),"In Progress",IF(L23<>"",IF(L23<J23,"Completed Early",IF(L23=J23,"Completed On Time","Delayed")),IF(TODAY()=I23,"Due to Start",IF(AND(I23>TODAY(),I23<=TODAY()+7),"Starts in "&(I23-TODAY())&" day"&IF((I23-TODAY())=1,"","s"),IF(TODAY()<I23,"Not Started","Delayed"))))))))),"Check Date") -> Not Started | N23: =IFERROR(IF(LEFT(M23,9)="Completed",1,IF(OR(M23="Not Started",M23="Due to Start"),0,IF(OR(M23="In Progress",M23="Delayed"),IF(K23="",0,MIN(0.99,NETWORKDAYS(K23,TODAY(),offday[Date])/MAX(1,NETWORKDAYS(K23,J23,offday[Date])))),0))),"") -> 0 | O23: =IFERROR(IF(NOT(ISNUMBER(J23)),"",IF(AND(L23<>"",ISNUMBER(L23),L23<=TODAY()),MAX(0,NETWORKDAYS(J23,L23,offday[Date])-1),IF(TODAY()>J23,MAX(0,NETWORKDAYS(J23,TODAY(),offday[Date])-1),"-"))),"-") -> - | P23: =IF(OR(NOT(ISNUMBER(I23)),NOT(ISNUMBER(J23))),"",(J23-I23+1)-NETWORKDAYS(I23,J23,offday[Date])) -> 7 | Q23: Feature comparison matrix, Visual and UI design quality, accessibility benchmarking, Information architecture, App store UX review mining, Innovation gap analysis
A24: 17 | B24: Benchmarking and Peer Study | C24: UXR Lead | D24: Build feature comparison matrix | E24: =IF(ISNUMBER(I24),"W"&MAX(0,INT((NETWORKDAYS(Dashboard!$B$3,I24,offday[Date])-1)/5)),"") -> W5 | F24: =IF(ISNUMBER(J24),"W"&MAX(0,INT((NETWORKDAYS(Dashboard!$B$3,J24,offday[Date])-1)/5)),"") -> W6 | H24: 3 | I24: =IF(H24="","",IF(ROW()=8,Dashboard!$B$3,IF(G24="",IFERROR(WORKDAY(J23,1,offday[Date]),"Check Predecessor"),IFERROR(WORKDAY(INDEX($J$8:$J$203,MATCH(G24,$A$8:$A$203,0)),1,offday[Date]),"Check Predecessor")))) -> 46205 | J24: =IF(H24="","",IF(ISNUMBER(I24),WORKDAY(I24,H24-1,offday[Date]),"Check Predecessor")) -> 46209 | M24: =IFERROR(IF(H24="","",IF(OR(NOT(ISNUMBER(I24)),NOT(ISNUMBER(J24))),"Check Plan",IF(AND(L24<>"",K24=""),"Check Actual Start",IF(AND(K24<>"",L24<>"",L24<K24),"Delayed",IF(AND(K24<>"",OR(L24="",L24>TODAY())),"In Progress",IF(L24<>"",IF(L24<J24,"Completed Early",IF(L24=J24,"Completed On Time","Delayed")),IF(TODAY()=I24,"Due to Start",IF(AND(I24>TODAY(),I24<=TODAY()+7),"Starts in "&(I24-TODAY())&" day"&IF((I24-TODAY())=1,"","s"),IF(TODAY()<I24,"Not Started","Delayed"))))))))),"Check Date") -> Not Started | N24: =IFERROR(IF(LEFT(M24,9)="Completed",1,IF(OR(M24="Not Started",M24="Due to Start"),0,IF(OR(M24="In Progress",M24="Delayed"),IF(K24="",0,MIN(0.99,NETWORKDAYS(K24,TODAY(),offday[Date])/MAX(1,NETWORKDAYS(K24,J24,offday[Date])))),0))),"") -> 0 | O24: =IFERROR(IF(NOT(ISNUMBER(J24)),"",IF(AND(L24<>"",ISNUMBER(L24),L24<=TODAY()),MAX(0,NETWORKDAYS(J24,L24,offday[Date])-1),IF(TODAY()>J24,MAX(0,NETWORKDAYS(J24,TODAY(),offday[Date])-1),"-"))),"-") -> - | P24: =IF(OR(NOT(ISNUMBER(I24)),NOT(ISNUMBER(J24))),"",(J24-I24+1)-NETWORKDAYS(I24,J24,offday[Date])) -> 2
A25: 18 | B25: Field Research | C25: UXR Ast | D25: Finalise UT Plan & Endorsement | E25: =IF(ISNUMBER(I25),"W"&MAX(0,INT((NETWORKDAYS(Dashboard!$B$3,I25,offday[Date])-1)/5)),"") -> W6 | F25: =IF(ISNUMBER(J25),"W"&MAX(0,INT((NETWORKDAYS(Dashboard!$B$3,J25,offday[Date])-1)/5)),"") -> W6 | G25: 17 | H25: 3 | I25: =IF(H25="","",IF(ROW()=8,Dashboard!$B$3,IF(G25="",IFERROR(WORKDAY(J24,1,offday[Date]),"Check Predecessor"),IFERROR(WORKDAY(INDEX($J$8:$J$203,MATCH(G25,$A$8:$A$203,0)),1,offday[Date]),"Check Predecessor")))) -> 46210 | J25: =IF(H25="","",IF(ISNUMBER(I25),WORKDAY(I25,H25-1,offday[Date]),"Check Predecessor")) -> 46212 | M25: =IFERROR(IF(H25="","",IF(OR(NOT(ISNUMBER(I25)),NOT(ISNUMBER(J25))),"Check Plan",IF(AND(L25<>"",K25=""),"Check Actual Start",IF(AND(K25<>"",L25<>"",L25<K25),"Delayed",IF(AND(K25<>"",OR(L25="",L25>TODAY())),"In Progress",IF(L25<>"",IF(L25<J25,"Completed Early",IF(L25=J25,"Completed On Time","Delayed")),IF(TODAY()=I25,"Due to Start",IF(AND(I25>TODAY(),I25<=TODAY()+7),"Starts in "&(I25-TODAY())&" day"&IF((I25-TODAY())=1,"","s"),IF(TODAY()<I25,"Not Started","Delayed"))))))))),"Check Date") -> Not Started | N25: =IFERROR(IF(LEFT(M25,9)="Completed",1,IF(OR(M25="Not Started",M25="Due to Start"),0,IF(OR(M25="In Progress",M25="Delayed"),IF(K25="",0,MIN(0.99,NETWORKDAYS(K25,TODAY(),offday[Date])/MAX(1,NETWORKDAYS(K25,J25,offday[Date])))),0))),"") -> 0 | O25: =IFERROR(IF(NOT(ISNUMBER(J25)),"",IF(AND(L25<>"",ISNUMBER(L25),L25<=TODAY()),MAX(0,NETWORKDAYS(J25,L25,offday[Date])-1),IF(TODAY()>J25,MAX(0,NETWORKDAYS(J25,TODAY(),offday[Date])-1),"-"))),"-") -> - | P25: =IF(OR(NOT(ISNUMBER(I25)),NOT(ISNUMBER(J25))),"",(J25-I25+1)-NETWORKDAYS(I25,J25,offday[Date])) -> 0
A26: 19 | B26: Field Research | C26: UXR Ast | D26: Prototype and Question Readiness | E26: =IF(ISNUMBER(I26),"W"&MAX(0,INT((NETWORKDAYS(Dashboard!$B$3,I26,offday[Date])-1)/5)),"") -> W6 | F26: =IF(ISNUMBER(J26),"W"&MAX(0,INT((NETWORKDAYS(Dashboard!$B$3,J26,offday[Date])-1)/5)),"") -> W8 | H26: 8 | I26: =IF(H26="","",IF(ROW()=8,Dashboard!$B$3,IF(G26="",IFERROR(WORKDAY(J25,1,offday[Date]),"Check Predecessor"),IFERROR(WORKDAY(INDEX($J$8:$J$203,MATCH(G26,$A$8:$A$203,0)),1,offday[Date]),"Check Predecessor")))) -> 46213 | J26: =IF(H26="","",IF(ISNUMBER(I26),WORKDAY(I26,H26-1,offday[Date]),"Check Predecessor")) -> 46224 | M26: =IFERROR(IF(H26="","",IF(OR(NOT(ISNUMBER(I26)),NOT(ISNUMBER(J26))),"Check Plan",IF(AND(L26<>"",K26=""),"Check Actual Start",IF(AND(K26<>"",L26<>"",L26<K26),"Delayed",IF(AND(K26<>"",OR(L26="",L26>TODAY())),"In Progress",IF(L26<>"",IF(L26<J26,"Completed Early",IF(L26=J26,"Completed On Time","Delayed")),IF(TODAY()=I26,"Due to Start",IF(AND(I26>TODAY(),I26<=TODAY()+7),"Starts in "&(I26-TODAY())&" day"&IF((I26-TODAY())=1,"","s"),IF(TODAY()<I26,"Not Started","Delayed"))))))))),"Check Date") -> Not Started | N26: =IFERROR(IF(LEFT(M26,9)="Completed",1,IF(OR(M26="Not Started",M26="Due to Start"),0,IF(OR(M26="In Progress",M26="Delayed"),IF(K26="",0,MIN(0.99,NETWORKDAYS(K26,TODAY(),offday[Date])/MAX(1,NETWORKDAYS(K26,J26,offday[Date])))),0))),"") -> 0 | O26: =IFERROR(IF(NOT(ISNUMBER(J26)),"",IF(AND(L26<>"",ISNUMBER(L26),L26<=TODAY()),MAX(0,NETWORKDAYS(J26,L26,offday[Date])-1),IF(TODAY()>J26,MAX(0,NETWORKDAYS(J26,TODAY(),offday[Date])-1),"-"))),"-") -> - | P26: =IF(OR(NOT(ISNUMBER(I26)),NOT(ISNUMBER(J26))),"",(J26-I26+1)-NETWORKDAYS(I26,J26,offday[Date])) -> 4 | Q26: Prototype: 8 days, Questions: 5 days
A27: 20 | B27: Field Research | C27: UXR Ast | D27: Moderator Recruitment | E27: =IF(ISNUMBER(I27),"W"&MAX(0,INT((NETWORKDAYS(Dashboard!$B$3,I27,offday[Date])-1)/5)),"") -> W8 | F27: =IF(ISNUMBER(J27),"W"&MAX(0,INT((NETWORKDAYS(Dashboard!$B$3,J27,offday[Date])-1)/5)),"") -> W8 | H27: 3 | I27: =IF(H27="","",IF(ROW()=8,Dashboard!$B$3,IF(G27="",IFERROR(WORKDAY(J26,1,offday[Date]),"Check Predecessor"),IFERROR(WORKDAY(INDEX($J$8:$J$203,MATCH(G27,$A$8:$A$203,0)),1,offday[Date]),"Check Predecessor")))) -> 46225 | J27: =IF(H27="","",IF(ISNUMBER(I27),WORKDAY(I27,H27-1,offday[Date]),"Check Predecessor")) -> 46227 | M27: =IFERROR(IF(H27="","",IF(OR(NOT(ISNUMBER(I27)),NOT(ISNUMBER(J27))),"Check Plan",IF(AND(L27<>"",K27=""),"Check Actual Start",IF(AND(K27<>"",L27<>"",L27<K27),"Delayed",IF(AND(K27<>"",OR(L27="",L27>TODAY())),"In Progress",IF(L27<>"",IF(L27<J27,"Completed Early",IF(L27=J27,"Completed On Time","Delayed")),IF(TODAY()=I27,"Due to Start",IF(AND(I27>TODAY(),I27<=TODAY()+7),"Starts in "&(I27-TODAY())&" day"&IF((I27-TODAY())=1,"","s"),IF(TODAY()<I27,"Not Started","Delayed"))))))))),"Check Date") -> Not Started | N27: =IFERROR(IF(LEFT(M27,9)="Completed",1,IF(OR(M27="Not Started",M27="Due to Start"),0,IF(OR(M27="In Progress",M27="Delayed"),IF(K27="",0,MIN(0.99,NETWORKDAYS(K27,TODAY(),offday[Date])/MAX(1,NETWORKDAYS(K27,J27,offday[Date])))),0))),"") -> 0 | O27: =IFERROR(IF(NOT(ISNUMBER(J27)),"",IF(AND(L27<>"",ISNUMBER(L27),L27<=TODAY()),MAX(0,NETWORKDAYS(J27,L27,offday[Date])-1),IF(TODAY()>J27,MAX(0,NETWORKDAYS(J27,TODAY(),offday[Date])-1),"-"))),"-") -> - | P27: =IF(OR(NOT(ISNUMBER(I27)),NOT(ISNUMBER(J27))),"",(J27-I27+1)-NETWORKDAYS(I27,J27,offday[Date])) -> 0
A28: 21 | B28: Field Research | C28: UXR Ast | D28: Branch Engagement + Confirmation | E28: =IF(ISNUMBER(I28),"W"&MAX(0,INT((NETWORKDAYS(Dashboard!$B$3,I28,offday[Date])-1)/5)),"") -> W6 | F28: =IF(ISNUMBER(J28),"W"&MAX(0,INT((NETWORKDAYS(Dashboard!$B$3,J28,offday[Date])-1)/5)),"") -> W6 | G28: 17 | H28: 3 | I28: =IF(H28="","",IF(ROW()=8,Dashboard!$B$3,IF(G28="",IFERROR(WORKDAY(J27,1,offday[Date]),"Check Predecessor"),IFERROR(WORKDAY(INDEX($J$8:$J$203,MATCH(G28,$A$8:$A$203,0)),1,offday[Date]),"Check Predecessor")))) -> 46210 | J28: =IF(H28="","",IF(ISNUMBER(I28),WORKDAY(I28,H28-1,offday[Date]),"Check Predecessor")) -> 46212 | M28: =IFERROR(IF(H28="","",IF(OR(NOT(ISNUMBER(I28)),NOT(ISNUMBER(J28))),"Check Plan",IF(AND(L28<>"",K28=""),"Check Actual Start",IF(AND(K28<>"",L28<>"",L28<K28),"Delayed",IF(AND(K28<>"",OR(L28="",L28>TODAY())),"In Progress",IF(L28<>"",IF(L28<J28,"Completed Early",IF(L28=J28,"Completed On Time","Delayed")),IF(TODAY()=I28,"Due to Start",IF(AND(I28>TODAY(),I28<=TODAY()+7),"Starts in "&(I28-TODAY())&" day"&IF((I28-TODAY())=1,"","s"),IF(TODAY()<I28,"Not Started","Delayed"))))))))),"Check Date") -> Not Started | N28: =IFERROR(IF(LEFT(M28,9)="Completed",1,IF(OR(M28="Not Started",M28="Due to Start"),0,IF(OR(M28="In Progress",M28="Delayed"),IF(K28="",0,MIN(0.99,NETWORKDAYS(K28,TODAY(),offday[Date])/MAX(1,NETWORKDAYS(K28,J28,offday[Date])))),0))),"") -> 0 | O28: =IFERROR(IF(NOT(ISNUMBER(J28)),"",IF(AND(L28<>"",ISNUMBER(L28),L28<=TODAY()),MAX(0,NETWORKDAYS(J28,L28,offday[Date])-1),IF(TODAY()>J28,MAX(0,NETWORKDAYS(J28,TODAY(),offday[Date])-1),"-"))),"-") -> - | P28: =IF(OR(NOT(ISNUMBER(I28)),NOT(ISNUMBER(J28))),"",(J28-I28+1)-NETWORKDAYS(I28,J28,offday[Date])) -> 0
A29: 22 | B29: Field Research | C29: UXR Ast | D29: UT Materials Prep + Dry Run | E29: =IF(ISNUMBER(I29),"W"&MAX(0,INT((NETWORKDAYS(Dashboard!$B$3,I29,offday[Date])-1)/5)),"") -> W6 | F29: =IF(ISNUMBER(J29),"W"&MAX(0,INT((NETWORKDAYS(Dashboard!$B$3,J29,offday[Date])-1)/5)),"") -> W7 | H29: 3 | I29: =IF(H29="","",IF(ROW()=8,Dashboard!$B$3,IF(G29="",IFERROR(WORKDAY(J28,1,offday[Date]),"Check Predecessor"),IFERROR(WORKDAY(INDEX($J$8:$J$203,MATCH(G29,$A$8:$A$203,0)),1,offday[Date]),"Check Predecessor")))) -> 46213 | J29: =IF(H29="","",IF(ISNUMBER(I29),WORKDAY(I29,H29-1,offday[Date]),"Check Predecessor")) -> 46217 | M29: =IFERROR(IF(H29="","",IF(OR(NOT(ISNUMBER(I29)),NOT(ISNUMBER(J29))),"Check Plan",IF(AND(L29<>"",K29=""),"Check Actual Start",IF(AND(K29<>"",L29<>"",L29<K29),"Delayed",IF(AND(K29<>"",OR(L29="",L29>TODAY())),"In Progress",IF(L29<>"",IF(L29<J29,"Completed Early",IF(L29=J29,"Completed On Time","Delayed")),IF(TODAY()=I29,"Due to Start",IF(AND(I29>TODAY(),I29<=TODAY()+7),"Starts in "&(I29-TODAY())&" day"&IF((I29-TODAY())=1,"","s"),IF(TODAY()<I29,"Not Started","Delayed"))))))))),"Check Date") -> Not Started | N29: =IFERROR(IF(LEFT(M29,9)="Completed",1,IF(OR(M29="Not Started",M29="Due to Start"),0,IF(OR(M29="In Progress",M29="Delayed"),IF(K29="",0,MIN(0.99,NETWORKDAYS(K29,TODAY(),offday[Date])/MAX(1,NETWORKDAYS(K29,J29,offday[Date])))),0))),"") -> 0 | O29: =IFERROR(IF(NOT(ISNUMBER(J29)),"",IF(AND(L29<>"",ISNUMBER(L29),L29<=TODAY()),MAX(0,NETWORKDAYS(J29,L29,offday[Date])-1),IF(TODAY()>J29,MAX(0,NETWORKDAYS(J29,TODAY(),offday[Date])-1),"-"))),"-") -> - | P29: =IF(OR(NOT(ISNUMBER(I29)),NOT(ISNUMBER(J29))),"",(J29-I29+1)-NETWORKDAYS(I29,J29,offday[Date])) -> 2
A30: 23 | B30: Field Research | C30: UXR Ast | D30: UT Field day | E30: =IF(ISNUMBER(I30),"W"&MAX(0,INT((NETWORKDAYS(Dashboard!$B$3,I30,offday[Date])-1)/5)),"") -> W7 | F30: =IF(ISNUMBER(J30),"W"&MAX(0,INT((NETWORKDAYS(Dashboard!$B$3,J30,offday[Date])-1)/5)),"") -> W10 | H30: 15 | I30: =IF(H30="","",IF(ROW()=8,Dashboard!$B$3,IF(G30="",IFERROR(WORKDAY(J29,1,offday[Date]),"Check Predecessor"),IFERROR(WORKDAY(INDEX($J$8:$J$203,MATCH(G30,$A$8:$A$203,0)),1,offday[Date]),"Check Predecessor")))) -> 46218 | J30: =IF(H30="","",IF(ISNUMBER(I30),WORKDAY(I30,H30-1,offday[Date]),"Check Predecessor")) -> 46238 | M30: =IFERROR(IF(H30="","",IF(OR(NOT(ISNUMBER(I30)),NOT(ISNUMBER(J30))),"Check Plan",IF(AND(L30<>"",K30=""),"Check Actual Start",IF(AND(K30<>"",L30<>"",L30<K30),"Delayed",IF(AND(K30<>"",OR(L30="",L30>TODAY())),"In Progress",IF(L30<>"",IF(L30<J30,"Completed Early",IF(L30=J30,"Completed On Time","Delayed")),IF(TODAY()=I30,"Due to Start",IF(AND(I30>TODAY(),I30<=TODAY()+7),"Starts in "&(I30-TODAY())&" day"&IF((I30-TODAY())=1,"","s"),IF(TODAY()<I30,"Not Started","Delayed"))))))))),"Check Date") -> Not Started | N30: =IFERROR(IF(LEFT(M30,9)="Completed",1,IF(OR(M30="Not Started",M30="Due to Start"),0,IF(OR(M30="In Progress",M30="Delayed"),IF(K30="",0,MIN(0.99,NETWORKDAYS(K30,TODAY(),offday[Date])/MAX(1,NETWORKDAYS(K30,J30,offday[Date])))),0))),"") -> 0 | O30: =IFERROR(IF(NOT(ISNUMBER(J30)),"",IF(AND(L30<>"",ISNUMBER(L30),L30<=TODAY()),MAX(0,NETWORKDAYS(J30,L30,offday[Date])-1),IF(TODAY()>J30,MAX(0,NETWORKDAYS(J30,TODAY(),offday[Date])-1),"-"))),"-") -> - | P30: =IF(OR(NOT(ISNUMBER(I30)),NOT(ISNUMBER(J30))),"",(J30-I30+1)-NETWORKDAYS(I30,J30,offday[Date])) -> 6 | Q30: Malaysia Assoc Blind
A31: 24 | B31: Field Research | C31: UXR Ast | D31: UT Report Compilation | E31: =IF(ISNUMBER(I31),"W"&MAX(0,INT((NETWORKDAYS(Dashboard!$B$3,I31,offday[Date])-1)/5)),"") -> W10 | F31: =IF(ISNUMBER(J31),"W"&MAX(0,INT((NETWORKDAYS(Dashboard!$B$3,J31,offday[Date])-1)/5)),"") -> W11 | H31: 5 | I31: =IF(H31="","",IF(ROW()=8,Dashboard!$B$3,IF(G31="",IFERROR(WORKDAY(J30,1,offday[Date]),"Check Predecessor"),IFERROR(WORKDAY(INDEX($J$8:$J$203,MATCH(G31,$A$8:$A$203,0)),1,offday[Date]),"Check Predecessor")))) -> 46239 | J31: =IF(H31="","",IF(ISNUMBER(I31),WORKDAY(I31,H31-1,offday[Date]),"Check Predecessor")) -> 46245 | M31: =IFERROR(IF(H31="","",IF(OR(NOT(ISNUMBER(I31)),NOT(ISNUMBER(J31))),"Check Plan",IF(AND(L31<>"",K31=""),"Check Actual Start",IF(AND(K31<>"",L31<>"",L31<K31),"Delayed",IF(AND(K31<>"",OR(L31="",L31>TODAY())),"In Progress",IF(L31<>"",IF(L31<J31,"Completed Early",IF(L31=J31,"Completed On Time","Delayed")),IF(TODAY()=I31,"Due to Start",IF(AND(I31>TODAY(),I31<=TODAY()+7),"Starts in "&(I31-TODAY())&" day"&IF((I31-TODAY())=1,"","s"),IF(TODAY()<I31,"Not Started","Delayed"))))))))),"Check Date") -> Not Started | N31: =IFERROR(IF(LEFT(M31,9)="Completed",1,IF(OR(M31="Not Started",M31="Due to Start"),0,IF(OR(M31="In Progress",M31="Delayed"),IF(K31="",0,MIN(0.99,NETWORKDAYS(K31,TODAY(),offday[Date])/MAX(1,NETWORKDAYS(K31,J31,offday[Date])))),0))),"") -> 0 | O31: =IFERROR(IF(NOT(ISNUMBER(J31)),"",IF(AND(L31<>"",ISNUMBER(L31),L31<=TODAY()),MAX(0,NETWORKDAYS(J31,L31,offday[Date])-1),IF(TODAY()>J31,MAX(0,NETWORKDAYS(J31,TODAY(),offday[Date])-1),"-"))),"-") -> - | P31: =IF(OR(NOT(ISNUMBER(I31)),NOT(ISNUMBER(J31))),"",(J31-I31+1)-NETWORKDAYS(I31,J31,offday[Date])) -> 2
